Workbook

Sheet Search
C11: Ticker | D11: Sector | E11: Index
C12: cnp | D12: =VLOOKUP(C12,Tickers!A:B,2,FALSE) -> Utilities | E12: =VLOOKUP(D12,Match_Sector!A1:B20,2,FALSE) -> XLU (Utilities)

Sheet Tickers
A1: Symbol | B1: Sector | C1: Description | D1: Price | E1: Price - Currency | F1: Price Change % 1 day | G1: Volume 1 day | H1: Relative Volume 1 day | I1: Market capitalization | J1: Market capitalization - Currency | K1: Price to earnings ratio | L1: Earnings per share diluted, Trailing 12 months | M1: Earnings per share diluted, Trailing 12 months - Currency | N1: Earnings per share diluted growth %, TTM YoY | O1: Dividend yield %, Trailing 12 months | P1: Analyst Rating
A2: A | B2: Health technology | C2: Agilent Technologies, Inc, | D2: 140.25 | E2: USD | F2: 1.6672708 | G2: 686264 | H2: 0.36478252 | I2: 3.9760716e+10 | J2: USD | K2: 30.692636 | L2: 4.5695 | M2: USD | N2: 3.2212157 | O2: 0.71910112 | P2: Buy
A3: AA | B3: Non-energy minerals | C3: Alcoa Corporation | D3: 59.85 | E3: USD | F3: 5.8542625 | G3: 2872398 | H3: 0.5338615 | I3: 1.5498997e+10 | J3: USD | K3: 13.593313 | L3: 4.4029 | M3: USD | O3: 0.70746374 | P3: Buy
A4: AACB | B4: Finance | C4: Artius II Acquisition Inc, | D4: 10.29 | E4: USD | F4: -0.097087379 | G4: 1399 | H4: 0.014722937 | I4: 284775741 | J4: USD | O4: 0 | P4: Neutral
A5: AAL | B5: Transportation | C5: American Airlines Group, Inc, | D5: 15.79 | E5: USD | F5: 2.002584 | G5: 14754574 | H5: 0.33120098 | I5: 1.0422765e+10 | J5: USD | K5: 18.982929 | L5: 0.8318 | M5: USD | N5: 158.32298 | O5: 0 | P5: Buy
A6: AAM | B6: Finance | C6: AA Mission Acquisition Corp, | D6: 10.65 | E6: USD | F6: 0.093984962 | G6: 219 | H6: 0.0066464945 | I6: 4.6832311e+08 | J6: USD | K6: 32.728949 | L6: 0.3254 | M6: USD | O6: 0 | P6: Neutral
A7: AAMI | B7: Finance | C7: Acadian Asset Management Inc, | D7: 50.32 | E7: USD | F7: 6.2051499 | G7: 40799 | H7: 0.21884095 | I7: 1.796883e+09 | J7: USD | K7: 21.228485 | L7: 2.3704 | M7: USD | N7: 44.307805 | O7: 0.084423808 | P7: Neutral
A8: AAOI | B8: Electronic technology | C8: Applied Optoelectronics, Inc, | D8: 36.83 | E8: USD | F8: -6.9949495 | G8: 3068444 | H8: 0.62960913 | I8: 2.5147483e+09 | J8: USD | L8: -3.2256 | M8: USD | N8: -56.112671 | O8: 0 | P8: Buy
A9: AAON | B9: Producer manufacturing | C9: AAON, Inc, | D9: 82.73 | E9: USD | F9: 4.4702614 | G9: 242466 | H9: 0.2364416 | I9: 6.7535857e+09 | J9: USD | K9: 68.678399 | L9: 1.2046 | M9: USD | N9: -47.273046 | O9: 0.50511428 | P9: Strong buy
A10: AAP | B10: Retail trade | C10: Advance Auto Parts Inc, | D10: 39.66 | E10: USD | F10: 1.9799434 | G10: 620171 | H10: 0.29039994 | I10: 2.3804823e+09 | J10: USD | L10: -6.3128 | M10: USD | N10: -966.42877 | O10: 2.5713551 | P10: Neutral
A11: AAPG | B11: Health technology | C11: Ascentage Pharma Group International Unsponsored ADR | D11: 26.7 | E11: USD | F11: 1.2514221 | G11: 478 | H11: 0.13278884 | I11: 2.4187896e+09 | J11: USD | L11: -2.0128 | M11: USD | N11: -189.56985 | O11: 0 | P11: Strong buy
A12: AAPL | B12: Electronic technology | C12: Apple Inc, | D12: 268.97 | E12: USD | F12: -0.75273975 | G12: 13645057 | H12: 0.33047289 | I12: 3.9743957e+12 | J12: USD | K12: 36.058343 | L12: 7.4593 | M12: USD | N12: 22.889998 | O12: 0.38005978 | P12: Buy
A13: AARD | B13: Health technology | C13: Aardvark Therapeutics, Inc, | D13: 13.01 | E13: USD | F13: -1.3646702 | G13: 80995 | H13: 0.33251636 | I13: 2.8327025e+08 | J13: USD | L13: -2.2465 | M13: USD | N13: 31.299694 | O13: 0 | P13: Strong buy
A14: AAT | B14: Finance | C14: American Assets Trust, Inc, | D14: 18.77 | E14: USD | F14: -0.053248136 | G14: 61230 | H14: 0.12408368 | I14: 1148444783 | J14: USD | K14: 18.476228 | L14: 1.0159 | M14: USD | N14: 5.0568769 | O14: 7.2417465 | P14: Neutral
A15: AAUC | B15: Non-energy minerals | C15: Allied Gold Corporation | D15: 23.87 | E15: USD | F15: 3.2886196 | G15: 318894 | H15: 0.44161832 | I15: 2.9609672e+09 | J15: USD | L15: -0.338896 | M15: USD | N15: 71.660821 | O15: 0 | P15: Strong buy
A16: AB | B16: Finance | C16: AllianceBernstein Holding L,P, | D16: 39.445 | E16: USD | F16: 2.0833333 | G16: 55417 | H16: 0.3706027 | I16: 3.5892287e+09 | J16: USD | K16: 12.997133 | L16: 3.0349 | M16: USD | N16: -12.920349 | O16: 8.9803313 | P16: Neutral
A17: ABBV | B17: Health technology | C17: AbbVie Inc, | D17: 218.84 | E17: USD | F17: -4.5658715 | G17: 2198322 | H17: 0.45614473 | I17: 3.8677445e+11 | J17: USD | K17: 165.12488 | L17: 1.3253 | M17: USD | N17: -53.780428 | O17: 2.8607562 | P17: Buy
A18: ABCB | B18: Finance | C18: Ameris Bancorp | D18: 76.345 | E18: USD | F18: 3.1968099 | G18: 63012 | H18: 0.14023836 | I18: 5.2155196e+09 | J18: USD | K18: 13.209163 | L18: 5.7797 | M18: USD | N18: 20.810602 | O18: 1.0813733 | P18: Buy
A19: ABEO | B19: Health technology | C19: Abeona Therapeutics Inc, | D19: 5.2 | E19: USD | F19: -2.0715631 | G19: 323638 | H19: 0.33168236 | I19: 2.8179507e+08 | J19: USD | K19: 4.4623702 | L19: 1.1653 | M19: USD | O19: 0 | P19: Strong buy
A20: ABG | B20: Retail trade | C20: Asbury Automotive Group Inc | D20: 240.5 | E20: USD | F20: 2.4450503 | G20: 64508 | H20: 0.31751251 | I20: 4.6754544e+09 | J20: USD | K20: 8.4370867 | L20: 28.5051 | M20: USD | N20: 61.15502 | O20: 0 | P20: Neutral
A21: ABM | B21: Commercial services | C21: ABM Industries Incorporated | D21: 43.63 | E21: USD | F21: 2.2258669 | G21: 130774 | H21: 0.1286185 | I21: 2.6255497e+09 | J21: USD | K21: 16.860533 | L21: 2.5877 | M21: USD | N21: 102.54383 | O21: 2.4835989 | P21: Buy
A22: ABNB | B22: Consumer services | C22: Airbnb, Inc, | D22: 136.52 | E22: USD | F22: 2.6388993 | G22: 1144134 | H22: 0.29883709 | I22: 8.403485e+10 | J22: USD | K22: 32.300194 | L22: 4.2266 | M22: USD | N22: 48.442384 | O22: 0 | P22: Neutral
A23: ABR | B23: Finance | C23: Arbor Realty Trust Inc | D23: 8.115 | E23: USD | F23: 2.0754717 | G23: 956352 | H23: 0.24668774 | I23: 1555899611 | J23: USD | K23: 10.370607 | L23: 0.7825 | M23: USD | N23: -39.668466 | O23: 16.72956 | P23: Sell
A24: ABR/PD | B24: Finance | C24: Arbor Realty Trust 6,375% Series D Cumulative Redeemable Preferred Stock, Liquidation Preference $25,00 per Share | D24: 17.385 | E24: USD | F24: 0.7826087 | G24: 4421 | H24: 0.17473065 | I24: 1555899611 | J24: USD | K24: 22.217252 | L24: 0.7825 | M24: USD | N24: -39.668466 | O24: 16.72956 | P24: Neutral
A25: ABR/PE | B25: Finance | C25: Arbor Realty Trust 6,25% Series E Cumulative Redeemable Preferred Stock | D25: 17.35 | E25: USD | F25: 0.28901734 | G25: 6046 | H25: 0.36780406 | I25: 1555899611 | J25: USD | K25: 22.172524 | L25: 0.7825 | M25: USD | N25: -39.668466 | O25: 16.72956 | P25: Neutral
A26: ABR/PF | B26: Finance | C26: Arbor Realty Trust 6,25% Series F Fixed-to-Floating Rate Cumulative Redeemable Preferred Stock, Liquidation Preference $25,00 per share | D26: 22 | E26: USD | F26: 0.54844607 | G26: 1417 | H26: 0.069123637 | I26: 1555899611 | J26: USD | K26: 28.115016 | L26: 0.7825 | M26: USD | N26: -39.668466 | O26: 16.72956 | P26: Neutral
A27: ABT | B27: Health technology | C27: Abbott Laboratories | D27: 124.655 | E27: USD | F27: 0.37442628 | G27: 1679609 | H27: 0.30568805 | I27: 2.1675909e+11 | J27: USD | K27: 15.635622 | L27: 7.9725 | M27: USD | N27: 142.45051 | O27: 1.900314 | P27: Buy
A28: ABTS | B28: Technology services | C28: Abits Group Inc | D28: 5.19 | E28: USD | F28: 0.77669903 | G28: 465 | H28: 0.10814205 | I28: 12300275 | J28: USD | L28: -0.5275 | M28: USD | N28: 86.254072 | O28: 0 | P28: Neutral
A29: ABVX | B29: Health technology | C29: Abivax SA Sponsored ADR | D29: 121.74 | E29: USD | F29: -8.9930478 | G29: 782568 | H29: 0.45554033 | I29: 1.0503443e+10 | J29: USD | O29: 0 | P29: Strong buy
A30: ABX | B30: Finance | C30: Abacus Global Management, Inc, | D30: 7.895 | E30: USD | F30: -0.31565657 | G30: 145339 | H30: 0.0084344601 | I30: 7.7175878e+08 | J30: USD | K30: 101.08835 | L30: 0.0781 | M30: USD | O30: 2.5252525 | P30: Strong buy
A31: ABXL | B31: Finance | C31: Abacus Global Management, Inc, 9,875% Fixed Rate Senior Notes due 2028 | D31: 25.59 | E31: USD | F31: 0.35294118 | G31: 7911 | H31: 2.1245569 | I31: 774202606 | J31: USD | K31: 327.65685 | L31: 0.0781 | M31: USD | O31: 2.5252525 | P31: Neutral
A32: ACA | B32: Non-energy minerals | C32: Arcosa, Inc, | D32: 109.15 | E32: USD | F32: 2.2099448 | G32: 29602 | H32: 0.15040146 | I32: 5.3532645e+09 | J32: USD | K32: 36.135205 | L32: 3.0206 | M32: USD | N32: 14.921625 | O32: 0.18728345 | P32: Strong buy
A33: ACAD | B33: Health technology | C33: ACADIA Pharmaceuticals Inc, | D33: 25.64 | E33: USD | F33: -2.472423 | G33: 307228 | H33: 0.23820233 | I33: 4.3378217e+09 | J33: USD | K33: 16.496172 | L33: 1.5543 | M33: USD | N33: 101.20388 | O33: 0 | P33: Buy
A34: ACEL | B34: Consumer services | C34: Accel Entertainment, Inc, | D34: 11.38 | E34: USD | F34: 0.087950748 | G34: 48557 | H34: 0.1012522 | I34: 9.4690642e+08 | J34: USD | K34: 22.525732 | L34: 0.5052 | M34: USD | N34: 0.73778664 | O34: 0 | P34: Strong buy
A35: ACET | B35: Health technology | C35: Adicet Bio, Inc, | D35: 8.2 | E35: USD | F35: -7.0294785 | G35: 109992 | H35: 0.44490407 | I35: 78543484 | J35: USD | L35: -20.2173 | M35: USD | N35: 25.887489 | O35: 0 | P35: Strong buy
A36: ACFN | B36: Electronic technology | C36: Acorn Energy, Inc, | D36: 18.6802 | E36: USD | F36: 22.73456 | G36: 35936 | H36: 0.44405232 | I36: 46786916 | J36: USD | K36: 7.0467388 | L36: 2.6509 | M36: USD | N36: 481.21026 | O36: 0 | P36: Neutral
A37: ACGL | B37: Finance | C37: Arch Capital Group Ltd, | D37: 94.99 | E37: USD | F37: 1.2039207 | G37: 433416 | H37: 0.21048823 | I37: 3.4445839e+10 | J37: USD | K37: 8.889284 | L37: 10.6859 | M37: USD | N37: -28.252214 | O37: 0 | P37: Buy
A38: ACGLN | B38: Finance | C38: Arch Capital Group Ltd, - Depositary Shares, each Representing a 1/1,000th Interest in a 4,550% Non-Cumulative Preferred Share, Series G | D38: 16.99 | E38: USD | F38: 0.29515939 | G38: 34193 | H38: 0.50881078 | I38: 3.4036072e+10 | J38: USD | K38: 1.5899456 | L38: 10.6859 | M38: USD | N38: -28.252214 | O38: 0 | P38: Neutral
A39: ACGLO | B39: Finance | C39: Arch Capital Group Ltd, - Depositary Shares Each Representing 1/1,000th Interest in a Share of5,45% Non-Cumulative Preferred Shares, Series F | D39: 20.72 | E39: USD | F39: 0.72921731 | G39: 12636 | H39: 0.29765382 | I39: 3.4036072e+10 | J39: USD | K39: 1.9390037 | L39: 10.6859 | M39: USD | N39: -28.252214 | O39: 0 | P39: Neutral
A40: ACHC | B40: Health services | C40: Acadia Healthcare Company, Inc, | D40: 14.05 | E40: USD | F40: -1.6794962 | G40: 728174 | H40: 0.31341144 | I40: 1.2962272e+09 | J40: USD | K40: 11.918901 | L40: 1.1788 | M40: USD | N40: -61.353354 | O40: 0 | P40: Buy
...

Sheet Tickers_500
A1: Ticker | B1: Sector | C1: Index
A2: AA | B2: =VLOOKUP(A2,Tickers!A:B,2,FALSE) -> Non-energy minerals | C2: =VLOOKUP(B2,Match_Sector!A:B,2,FALSE) -> XLB (Materials)
A3: AAL | B3: =VLOOKUP(A3,Tickers!A:B,2,FALSE) -> Transportation | C3: =VLOOKUP(B3,Match_Sector!A:B,2,FALSE) -> XLI (Industrials)
A4: AAOI | B4: =VLOOKUP(A4,Tickers!A:B,2,FALSE) -> Electronic technology | C4: =VLOOKUP(B4,Match_Sector!A:B,2,FALSE) -> XLK (Technology)
A5: ABR | B5: =VLOOKUP(A5,Tickers!A:B,2,FALSE) -> Finance | C5: =VLOOKUP(B5,Match_Sector!A:B,2,FALSE) -> XLF (Financials)
A6: ACHC | B6: =VLOOKUP(A6,Tickers!A:B,2,FALSE) -> Health services | C6: =VLOOKUP(B6,Match_Sector!A:B,2,FALSE) -> XLV (Health Care)
A7: ACHR | B7: =VLOOKUP(A7,Tickers!A:B,2,FALSE) -> Electronic technology | C7: =VLOOKUP(B7,Match_Sector!A:B,2,FALSE) -> XLK (Technology)
A8: ACI | B8: =VLOOKUP(A8,Tickers!A:B,2,FALSE) -> Retail trade | C8: =VLOOKUP(B8,Match_Sector!A:B,2,FALSE) -> XLY (Consumer Discretionary)*
A9: ACVA | B9: =VLOOKUP(A9,Tickers!A:B,2,FALSE) -> Technology services | C9: =VLOOKUP(B9,Match_Sector!A:B,2,FALSE) -> XLK (Technology)
A10: ADM | B10: =VLOOKUP(A10,Tickers!A:B,2,FALSE) -> Process industries | C10: =VLOOKUP(B10,Match_Sector!A:B,2,FALSE) -> XLB (Materials)
A11: ADMA | B11: =VLOOKUP(A11,Tickers!A:B,2,FALSE) -> Health technology | C11: =VLOOKUP(B11,Match_Sector!A:B,2,FALSE) -> XLV (Health Care)
A12: ADPT | B12: =VLOOKUP(A12,Tickers!A:B,2,FALSE) -> Health technology | C12: =VLOOKUP(B12,Match_Sector!A:B,2,FALSE) -> XLV (Health Care)
A13: ADT | B13: =VLOOKUP(A13,Tickers!A:B,2,FALSE) -> Commercial services | C13: =VLOOKUP(B13,Match_Sector!A:B,2,FALSE) -> XLI (Industrials)
... A493: ZM | B493: =VLOOKUP(A493,Tickers!A:B,2,FALSE) -> Technology services | C493: =VLOOKUP(B493,Match_Sector!A:B,2,FALSE) -> XLK (Technology)

Sheet Match_Sector
A1: TradingView sector | B1: Closest SPDR sector ETF
A2: Commercial Services | B2: XLI (Industrials)
A3: Communications | B3: XLC (Communication Services)
A4: Consumer Durables | B4: XLY (Consumer Discretionary)
A5: Consumer non-durables | B5: XLY (Consumer Discretionary)
A6: Consumer Services | B6: XLY (Consumer Discretionary)
A7: Distribution services | B7: XLI (Industrials)
A8: Electronic Technology | B8: XLK (Technology)
A9: Energy Minerals | B9: XLE (Energy)
A10: Finance | B10: XLF (Financials)
A11: Health Services | B11: XLV (Health Care)
A12: Health Technology | B12: XLV (Health Care)
... A20: Utilities | B20: XLU (Utilities)

Sheet Match_Index
A1: Closest SPDR sector ETF | B1: TradingView sector
A2: XLB (Materials) | B2: Non-energy minerals
A3: XLB (Materials) | B3: Process Industries
A4: XLC (Communication Services) | B4: Communications
A5: XLE (Energy) | B5: Energy Minerals
A6: XLF (Financials) | B6: Finance
A7: XLI (Industrials) | B7: Commercial Services
A8: XLI (Industrials) | B8: Distribution services
A9: XLI (Industrials) | B9: Industrial services
A10: XLI (Industrials) | B10: Producer Manufacturing
A11: XLI (Industrials) | B11: Transportation
A12: XLK (Technology) | B12: Electronic Technology
... A19: XLY (Consumer Discretionary)* | B19: Retail Trade
